<?xml version="1.0" encoding="utf-8"?>
<!-- This URDF was automatically created by SolidWorks to URDF Exporter! Originally created by Stephen Brawner (brawner@gmail.com) 
     Commit Version: 1.6.0-1-g15f4949  Build Version: 1.6.7594.29634
     For more information, please see http://wiki.ros.org/sw_urdf_exporter -->

<robot name="leg" xmlns:xacro="http://www.ros.org/wiki/xacro">

  <xacro:macro name="leg" params="limb_name lower_upper_limb upper_upper_limb lower_lower_limb upper_lower_limb">

    <xacro:property name="damp" value="0.3"/>
    <xacro:property name="friction" value="0.2"/>
    <xacro:property name="mu1" value="0.7"/>
    <xacro:property name="mu2" value="0.7"/>

    <xacro:macro name="default_transmission" params="name joint_name">
      <transmission name="transmission_for_${name}">
          <type>transmission_interface/SimpleTransmission</type>
          <joint name="${joint_name}">
              <hardwareInterface>hardware_interface/EffortJointInterface</hardwareInterface>
          </joint>

          <actuator name="motor_for_${name}">
              <hardwareInterface>hardware_interface/EffortJointInterface</hardwareInterface>
              <mechanicalReduction>1</mechanicalReduction>
          </actuator>

      </transmission>
    </xacro:macro>

  <!-- Swing link -->
  <link
    name="swing_link_${limb_name}">
    <inertial>
      <origin
        xyz="-7.9456E-18 -0.07256 -0.003468" 
        rpy="0 0 0" />
      <mass
        value="0.39795" />
      <inertia
        ixx="0.0010374"
        ixy="7.6425E-21"
        ixz="2.8543E-20"
        izz="0.0010217"
        iyz="-3.1456E-05"
        iyy="0.00014871" />
    </inertial>
    <visual>
      <origin
        xyz="0 0 0"
        rpy="0 0 0" />
      <geometry>
        <mesh
          filename="package://tachyon/meshes/swing_link_x.STL" />
      </geometry>
      <material
        name="">
        <color
          rgba="0 0 0 1" />
      </material>
    </visual>
    <collision>
      <origin
        xyz="0 0 0"
        rpy="0 0 0" />
      <geometry>
        <mesh
          filename="package://tachyon/meshes/swing_link_x.STL" />
      </geometry>
    </collision>
  </link>

  <!-- Upper limb link -->
  <link
    name="upper_limb_link_${limb_name}">
    <inertial>
      <origin
        xyz="-3.4081E-17 -0.17 0.03"
        rpy="0 0 0" />
      <mass
        value="0.75908" />
      <inertia
        ixx="0.0073043"
        ixy="3.2495E-20"
        ixz="-3.9739E-20"
        iyy="0.00027252"
        iyz="4.4999E-20"
        izz="0.0072881" />
    </inertial>
    <visual>
      <origin
        xyz="0 0 0"
        rpy="0 0 0" />
      <geometry>
        <mesh
          filename="package://tachyon/meshes/upper_limb_link_x.STL" />
      </geometry>
      <material
        name="">
        <color
          rgba="0 0 0 1" />
      </material>
    </visual>
    <collision>
      <origin
        xyz="0 0 0"
        rpy="0 0 0" />
      <geometry>
        <mesh
          filename="package://tachyon/meshes/upper_limb_link_x.STL" />
      </geometry>
    </collision>
  </link>

  <!-- Swing link to upper limb joint -->
  <joint
    name="swing_link_to_upper_limb_link_joint_${limb_name}"
    type="revolute">
    <origin
      xyz="0 -0.1 -0.08075"
      rpy="1.5708 0 0" />
    <parent
      link="swing_link_${limb_name}" />
    <child
      link="upper_limb_link_${limb_name}" />
    <axis
      xyz="0 0 1" />
    <limit
      lower="${lower_upper_limb}"
      upper="${upper_upper_limb}"
      effort="1000"
      velocity="0.5" />
      <dynamics
      damping="${damp}"
      friction="${friction}" />
  </joint>

  <!-- Lower limb link -->
  <link
    name="lower_limb_link_${limb_name}">
    <inertial>
      <origin
        xyz="-1.0068E-16 -0.15594 0.0225"
        rpy="0 0 0" />
      <mass
        value="0.70447" />
      <inertia
        ixx="0.0072506"
        ixy="2.1119E-20"
        ixz="-3.4994E-20"
        iyy="0.00023845"
        iyz="6.4026E-20"
        izz="0.0072513" />
    </inertial>
    <visual>
      <origin
        xyz="0 0 0"
        rpy="0 0 0" />
      <geometry>
        <mesh
          filename="package://tachyon/meshes/lower_limb_link_x.STL" />
      </geometry>
      <material
        name="">
        <color
          rgba="0 0 0 1" />
      </material>
    </visual>
    <collision>
      <origin
        xyz="0 0 0"
        rpy="0 0 0" />
      <geometry>
        <mesh
          filename="package://tachyon/meshes/lower_limb_link_x.STL" />
      </geometry>
    </collision>
  </link>

  <!-- Upper limb to lower limb joint -->
  <joint
    name="upper_limb_link_to_lower_limb_link_joint_${limb_name}"
    type="revolute">
    <origin
      xyz="0 -0.39825 0.0075"
      rpy="0 0 0" />
    <parent
      link="upper_limb_link_${limb_name}" />
    <child
      link="lower_limb_link_${limb_name}" />
    <axis
      xyz="0 0 1" />
    <limit
      lower="${lower_lower_limb}"
      upper="${upper_lower_limb}"
      effort="1000"
      velocity="0.5" />
      <dynamics
      damping="${damp}"
      friction="${friction}" />
  </joint>

  <xacro:default_transmission name="swing_link_to_upper_limb_${limb_name}" joint_name="swing_link_to_upper_limb_link_joint_${limb_name}"/>

  <xacro:default_transmission name="upper_limb_to_lower_limb_${limb_name}" joint_name="upper_limb_link_to_lower_limb_link_joint_${limb_name}"/>

  <gazebo reference="swing_link_${limb_name}">
    <selfCollide>true</selfCollide>
    <mu1>${mu1}</mu1>
    <mu2>${mu2}</mu2>
  </gazebo>

  <gazebo reference="upper_limb_link_${limb_name}">
    <selfCollide>true</selfCollide>
    <mu1>${mu1}</mu1>
    <mu2>${mu2}</mu2>      
  </gazebo>

  <gazebo reference="lower_limb_link_${limb_name}">
    <selfCollide>true</selfCollide>
    <mu1>${mu1}</mu1>
    <mu2>${mu2}</mu2>      
  </gazebo>

</xacro:macro>

</robot>